Certainly!

- **Example:**

```java
public class Example {
    public static void main(String[] args) {
        try {
            int result = divide(10, 0);
            System.out.println("Result: " + result);
        } catch (ArithmeticException e) {
            System.out.println("Caught ArithmeticException: " + e.getMessage());
        }
    }

    public static int divide(int dividend, int divisor) {
        return dividend / divisor;
    }
}
```

- **Explanation:**

    - The `try` block attempts the division operation.
    - If an `ArithmeticException` occurs, control transfers to the `catch` block.
    - The `catch` block handles the exception gracefully.

- **Behind the scenes:**

    - When an exception occurs within the `try` block, Java jumps to the corresponding `catch` block.
    - If no match is found, the exception propagates up the call stack.
    - This mechanism ensures the program handles exceptions without crashing.
----
- **Note:** When we pass the parameter into the catch block `(ArithmeticException e)`, an instance of the ArithmeticException class is automatically created like that :-
- (`ArithmeticException e = new ArithmeticException();`).
- For example:
  ```javascript
  catch(ArithmeticException e) {
      // Code to handle the exception
  }
  ```
- Inside this block, `e` is an object of type `ArithmeticException`.
- It is automatically instantiated when an exception of type `ArithmeticException` is caught.
- This object `e` allows access to the methods and variables defined within the ArithmeticException class, enabling further handling of the exception.